<mujoco model="engineer">
  <compiler angle="radian" meshdir="../mujoco_meshes/"/>
    <asset>
        <texture type="skybox" builtin="gradient" rgb1="0.3 0.5 0.7" rgb2="0 0 0" width="512" height="512" />
        <texture name="texplane" type="2d" builtin="checker" rgb1=".2 .3 .4" rgb2=".1 0.15 0.2" width="512" height="512" mark="cross" markrgb=".8 .8 .8" />
        <material name="matplane" reflectance="0.3" texture="texplane" texrepeat="1 1" texuniform="true" />
    <mesh name="base_link" file="base_link.STL"/>
    <mesh name="right_mecanum_wheel" file="right_mecanum_wheel.STL"/>
    <mesh name="left_mecanum_wheel" file="left_mecanum_wheel.STL"/>
  </asset>
  <default>
     <joint type="hinge" limited="true"/>
  </default>
  
  <worldbody>
    <light directional="true" diffuse=".4 .4 .4" specular="0.1 0.1 0.1" pos="0 0 5.0" dir="0 0 -1" castshadow="false" />
    <light directional="true" diffuse=".6 .6 .6" specular="0.2 0.2 0.2" pos="0 0 4" dir="0 0 -1" />
    <geom name="floor" type="plane" pos="0 0 0" size="15 15 1" material="matplane" margin="0.001" condim="3" friction="1 0.005 0.0001" />
    <body name="base_link">
      <freejoint name="root"/>
      <inertial pos="0.0147696 -0.0277071 0.0578145" quat="-0.00103407 0.707179 0.000451076 0.707034" mass="10.0515" diaginertia="0.0464541 0.0356236 0.019351"/>
      <geom type="mesh" contype="0" conaffinity="0" group="1" density="0" rgba="0.792157 0.819608 0.933333 1" mesh="base_link"/>
      <body name="left_front_wheel" pos="0.19727 0.223 0.000889">
        <inertial pos="0 0 0" quat="0.707107 0 0 0.707107" mass="0.4235" diaginertia="0.0007398 0.0004122 0.0004122"/>
        <joint name="left_front_wheel_joint" pos="0 0 0" axis="0 1 0" limited="true" range="-1000000000 1000000000" frictionloss="0.05"/>
        <geom type="mesh" contype="0" conaffinity="0" group="1" density="0" rgba="0.792157 0.819608 0.933333 1" mesh="right_mecanum_wheel"/>
        <body name="left_front_roller_0" pos="0 0 -0.068">
          <inertial pos="0 0 0" mass="0.036" diaginertia="3.128e-06 3.128e-06 3.128e-06"/>
          <joint name="left_front_roller_0_joint" pos="0 0 0" axis="0.707107 -0.707107 0" limited="false" frictionloss="0.001"/>
          <geom size="0.009"/>
        </body>
        <body name="left_front_roller_1" pos="0.0260414 0 -0.062816">
          <inertial pos="0 0 0" mass="0.036" diaginertia="3.128e-06 3.128e-06 3.128e-06"/>
          <joint name="left_front_roller_1_joint" pos="0 0 0" axis="0.6532 -0.707107 0.270795" limited="false" frictionloss="0.001"/>
          <geom size="0.009"/>
        </body>
        <body name="left_front_roller_2" pos="0.0481122 0 -0.0480543">
          <inertial pos="0 0 0" mass="0.036" diaginertia="3.128e-06 3.128e-06 3.128e-06"/>
          <joint name="left_front_roller_2_joint" pos="0 0 0" axis="0.499699 -0.707107 0.500301" limited="false" frictionloss="0.001"/>
          <geom size="0.009"/>
        </body>
        <body name="left_front_roller_3" pos="0.0628473 0 -0.0259657">
          <inertial pos="0 0 0" mass="0.036" diaginertia="3.128e-06 3.128e-06 3.128e-06"/>
          <joint name="left_front_roller_3_joint" pos="0 0 0" axis="0.270008 -0.707107 0.653525" limited="false" frictionloss="0.001"/>
          <geom size="0.009"/>
        </body>
        <body name="left_front_roller_4" pos="0.068 0 8.18498e-05">
          <inertial pos="0 0 0" mass="0.036" diaginertia="3.128e-06 3.128e-06 3.128e-06"/>
          <joint name="left_front_roller_4_joint" pos="0 0 0" axis="-0.000851125 -0.707107 0.707106" limited="false" frictionloss="0.001"/>
          <geom size="0.009"/>
        </body>
        <body name="left_front_roller_5" pos="0.0627846 0 0.026117">
          <inertial pos="0 0 0" mass="0.036" diaginertia="3.128e-06 3.128e-06 3.128e-06"/>
          <joint name="left_front_roller_5_joint" pos="0 0 0" axis="-0.271581 -0.707107 0.652874" limited="false" frictionloss="0.001"/>
          <geom size="0.009"/>
        </body>
        <body name="left_front_roller_6" pos="0.0479964 0 0.04817">
          <inertial pos="0 0 0" mass="0.036" diaginertia="3.128e-06 3.128e-06 3.128e-06"/>
          <joint name="left_front_roller_6_joint" pos="0 0 0" axis="-0.500902 -0.707107 0.499096" limited="false" frictionloss="0.001"/>
          <geom size="0.009"/>
        </body>
        <body name="left_front_roller_7" pos="0.0258901 0 0.0628785">
          <inertial pos="0 0 0" mass="0.036" diaginertia="3.128e-06 3.128e-06 3.128e-06"/>
          <joint name="left_front_roller_7_joint" pos="0 0 0" axis="-0.65385 -0.707107 0.269221" limited="false" frictionloss="0.001"/>
          <geom size="0.009"/>
        </body>
        <body name="left_front_roller_8" pos="-0.000163699 0 0.0679998">
          <inertial pos="0 0 0" mass="0.036" diaginertia="3.128e-06 3.128e-06 3.128e-06"/>
          <joint name="left_front_roller_8_joint" pos="0 0 0" axis="-0.707105 -0.707107 -0.00170225" limited="false" frictionloss="0.001"/>
          <geom size="0.009"/>
        </body>
        <body name="left_front_roller_9" pos="-0.0261925 0 0.0627531">
          <inertial pos="0 0 0" mass="0.036" diaginertia="3.128e-06 3.128e-06 3.128e-06"/>
          <joint name="left_front_roller_9_joint" pos="0 0 0" axis="-0.652546 -0.707107 -0.272366" limited="false" frictionloss="0.001"/>
          <geom size="0.009"/>
        </body>
        <body name="left_front_roller_10" pos="-0.0482277 0 0.0479384">
          <inertial pos="0 0 0" mass="0.036" diaginertia="3.128e-06 3.128e-06 3.128e-06"/>
          <joint name="left_front_roller_10_joint" pos="0 0 0" axis="-0.498493 -0.707107 -0.501502" limited="false" frictionloss="0.001"/>
          <geom size="0.009"/>
        </body>
        <body name="left_front_roller_11" pos="-0.0629096 0 0.0258144">
          <inertial pos="0 0 0" mass="0.036" diaginertia="3.128e-06 3.128e-06 3.128e-06"/>
          <joint name="left_front_roller_11_joint" pos="0 0 0" axis="-0.268434 -0.707107 -0.654174" limited="false" frictionloss="0.001"/>
          <geom size="0.009"/>
        </body>
        <body name="left_front_roller_12" pos="-0.0679996 0 -0.000245549">
          <inertial pos="0 0 0" mass="0.036" diaginertia="3.128e-06 3.128e-06 3.128e-06"/>
          <joint name="left_front_roller_12_joint" pos="0 0 0" axis="0.00255337 -0.707107 -0.707102" limited="false" frictionloss="0.001"/>
          <geom size="0.009"/>
        </body>
        <body name="left_front_roller_13" pos="-0.0627215 0 -0.026268">
          <inertial pos="0 0 0" mass="0.036" diaginertia="3.128e-06 3.128e-06 3.128e-06"/>
          <joint name="left_front_roller_13_joint" pos="0 0 0" axis="0.273152 -0.707107 -0.652218" limited="false" frictionloss="0.001"/>
          <geom size="0.009"/>
        </body>
        <body name="left_front_roller_14" pos="-0.0478803 0 -0.0482854">
          <inertial pos="0 0 0" mass="0.036" diaginertia="3.128e-06 3.128e-06 3.128e-06"/>
          <joint name="left_front_roller_14_joint" pos="0 0 0" axis="0.502102 -0.707107 -0.497889" limited="false" frictionloss="0.001"/>
          <geom size="0.009"/>
        </body>
        <body name="left_front_roller_15" pos="-0.0257386 0 -0.0629406">
          <inertial pos="0 0 0" mass="0.036" diaginertia="3.128e-06 3.128e-06 3.128e-06"/>
          <joint name="left_front_roller_15_joint" pos="0 0 0" axis="0.654496 -0.707107 -0.267647" limited="false" frictionloss="0.001"/>
          <geom size="0.009"/>
        </body>
      </body>
      <body name="right_front_wheel" pos="0.19727 -0.223 0.000889">
        <inertial pos="0 0 0" quat="0.707107 0 0 0.707107" mass="0.4235" diaginertia="0.0007398 0.0004122 0.0004122"/>
        <joint name="right_front_wheel_joint" pos="0 0 0" axis="0 1 0" limited="true" range="-1000000000 1000000000" frictionloss="0.05"/>
        <geom type="mesh" contype="0" conaffinity="0" group="1" density="0" rgba="0.792157 0.819608 0.933333 1" mesh="left_mecanum_wheel"/>
        <body name="right_front_roller_0" pos="0 0 -0.068">
          <inertial pos="0 0 0" mass="0.036" diaginertia="3.128e-06 3.128e-06 3.128e-06"/>
          <joint name="right_front_roller_0_joint" pos="0 0 0" axis="0.707107 0.707107 0" limited="false" frictionloss="0.001"/>
          <geom size="0.009"/>
        </body>
        <body name="right_front_roller_1" pos="0.0260414 0 -0.062816">
          <inertial pos="0 0 0" mass="0.036" diaginertia="3.128e-06 3.128e-06 3.128e-06"/>
          <joint name="right_front_roller_1_joint" pos="0 0 0" axis="0.6532 0.707107 0.270795" limited="false" frictionloss="0.001"/>
          <geom size="0.009"/>
        </body>
        <body name="right_front_roller_2" pos="0.0481122 0 -0.0480543">
          <inertial pos="0 0 0" mass="0.036" diaginertia="3.128e-06 3.128e-06 3.128e-06"/>
          <joint name="right_front_roller_2_joint" pos="0 0 0" axis="0.499699 0.707107 0.500301" limited="false" frictionloss="0.001"/>
          <geom size="0.009"/>
        </body>
        <body name="right_front_roller_3" pos="0.0628473 0 -0.0259657">
          <inertial pos="0 0 0" mass="0.036" diaginertia="3.128e-06 3.128e-06 3.128e-06"/>
          <joint name="right_front_roller_3_joint" pos="0 0 0" axis="0.270008 0.707107 0.653525" limited="false" frictionloss="0.001"/>
          <geom size="0.009"/>
        </body>
        <body name="right_front_roller_4" pos="0.068 0 8.18498e-05">
          <inertial pos="0 0 0" mass="0.036" diaginertia="3.128e-06 3.128e-06 3.128e-06"/>
          <joint name="right_front_roller_4_joint" pos="0 0 0" axis="-0.000851125 0.707107 0.707106" limited="false" frictionloss="0.001"/>
          <geom size="0.009"/>
        </body>
        <body name="right_front_roller_5" pos="0.0627846 0 0.026117">
          <inertial pos="0 0 0" mass="0.036" diaginertia="3.128e-06 3.128e-06 3.128e-06"/>
          <joint name="right_front_roller_5_joint" pos="0 0 0" axis="-0.271581 0.707107 0.652874" limited="false" frictionloss="0.001"/>
          <geom size="0.009"/>
        </body>
        <body name="right_front_roller_6" pos="0.0479964 0 0.04817">
          <inertial pos="0 0 0" mass="0.036" diaginertia="3.128e-06 3.128e-06 3.128e-06"/>
          <joint name="right_front_roller_6_joint" pos="0 0 0" axis="-0.500902 0.707107 0.499096" limited="false" frictionloss="0.001"/>
          <geom size="0.009"/>
        </body>
        <body name="right_front_roller_7" pos="0.0258901 0 0.0628785">
          <inertial pos="0 0 0" mass="0.036" diaginertia="3.128e-06 3.128e-06 3.128e-06"/>
          <joint name="right_front_roller_7_joint" pos="0 0 0" axis="-0.65385 0.707107 0.269221" limited="false" frictionloss="0.001"/>
          <geom size="0.009"/>
        </body>
        <body name="right_front_roller_8" pos="-0.000163699 0 0.0679998">
          <inertial pos="0 0 0" mass="0.036" diaginertia="3.128e-06 3.128e-06 3.128e-06"/>
          <joint name="right_front_roller_8_joint" pos="0 0 0" axis="-0.707105 0.707107 -0.00170225" limited="false" frictionloss="0.001"/>
          <geom size="0.009"/>
        </body>
        <body name="right_front_roller_9" pos="-0.0261925 0 0.0627531">
          <inertial pos="0 0 0" mass="0.036" diaginertia="3.128e-06 3.128e-06 3.128e-06"/>
          <joint name="right_front_roller_9_joint" pos="0 0 0" axis="-0.652546 0.707107 -0.272366" limited="false" frictionloss="0.001"/>
          <geom size="0.009"/>
        </body>
        <body name="right_front_roller_10" pos="-0.0482277 0 0.0479384">
          <inertial pos="0 0 0" mass="0.036" diaginertia="3.128e-06 3.128e-06 3.128e-06"/>
          <joint name="right_front_roller_10_joint" pos="0 0 0" axis="-0.498493 0.707107 -0.501502" limited="false" frictionloss="0.001"/>
          <geom size="0.009"/>
        </body>
        <body name="right_front_roller_11" pos="-0.0629096 0 0.0258144">
          <inertial pos="0 0 0" mass="0.036" diaginertia="3.128e-06 3.128e-06 3.128e-06"/>
          <joint name="right_front_roller_11_joint" pos="0 0 0" axis="-0.268434 0.707107 -0.654174" limited="false" frictionloss="0.001"/>
          <geom size="0.009"/>
        </body>
        <body name="right_front_roller_12" pos="-0.0679996 0 -0.000245549">
          <inertial pos="0 0 0" mass="0.036" diaginertia="3.128e-06 3.128e-06 3.128e-06"/>
          <joint name="right_front_roller_12_joint" pos="0 0 0" axis="0.00255337 0.707107 -0.707102" limited="false" frictionloss="0.001"/>
          <geom size="0.009"/>
        </body>
        <body name="right_front_roller_13" pos="-0.0627215 0 -0.026268">
          <inertial pos="0 0 0" mass="0.036" diaginertia="3.128e-06 3.128e-06 3.128e-06"/>
          <joint name="right_front_roller_13_joint" pos="0 0 0" axis="0.273152 0.707107 -0.652218" limited="false" frictionloss="0.001"/>
          <geom size="0.009"/>
        </body>
        <body name="right_front_roller_14" pos="-0.0478803 0 -0.0482854">
          <inertial pos="0 0 0" mass="0.036" diaginertia="3.128e-06 3.128e-06 3.128e-06"/>
          <joint name="right_front_roller_14_joint" pos="0 0 0" axis="0.502102 0.707107 -0.497889" limited="false" frictionloss="0.001"/>
          <geom size="0.009"/>
        </body>
        <body name="right_front_roller_15" pos="-0.0257386 0 -0.0629406">
          <inertial pos="0 0 0" mass="0.036" diaginertia="3.128e-06 3.128e-06 3.128e-06"/>
          <joint name="right_front_roller_15_joint" pos="0 0 0" axis="0.654496 0.707107 -0.267647" limited="false" frictionloss="0.001"/>
          <geom size="0.009"/>
        </body>
      </body>
      <body name="left_rear_wheel" pos="-0.19727 0.223 0.000889">
        <inertial pos="0 0 0" quat="0.707107 0 0 0.707107" mass="0.4235" diaginertia="0.0007398 0.0004122 0.0004122"/>
        <joint name="left_rear_wheel_joint" pos="0 0 0" axis="0 1 0" limited="true" range="-1000000000 1000000000" frictionloss="0.05"/>
        <geom type="mesh" contype="0" conaffinity="0" group="1" density="0" rgba="0.792157 0.819608 0.933333 1" mesh="left_mecanum_wheel"/>
        <body name="left_rear_roller_0" pos="0 0 -0.068">
          <inertial pos="0 0 0" mass="0.036" diaginertia="3.128e-06 3.128e-06 3.128e-06"/>
          <joint name="left_rear_roller_0_joint" pos="0 0 0" axis="0.707107 0.707107 0" limited="false" frictionloss="0.001"/>
          <geom size="0.009"/>
        </body>
        <body name="left_rear_roller_1" pos="0.0260414 0 -0.062816">
          <inertial pos="0 0 0" mass="0.036" diaginertia="3.128e-06 3.128e-06 3.128e-06"/>
          <joint name="left_rear_roller_1_joint" pos="0 0 0" axis="0.6532 0.707107 0.270795" limited="false" frictionloss="0.001"/>
          <geom size="0.009"/>
        </body>
        <body name="left_rear_roller_2" pos="0.0481122 0 -0.0480543">
          <inertial pos="0 0 0" mass="0.036" diaginertia="3.128e-06 3.128e-06 3.128e-06"/>
          <joint name="left_rear_roller_2_joint" pos="0 0 0" axis="0.499699 0.707107 0.500301" limited="false" frictionloss="0.001"/>
          <geom size="0.009"/>
        </body>
        <body name="left_rear_roller_3" pos="0.0628473 0 -0.0259657">
          <inertial pos="0 0 0" mass="0.036" diaginertia="3.128e-06 3.128e-06 3.128e-06"/>
          <joint name="left_rear_roller_3_joint" pos="0 0 0" axis="0.270008 0.707107 0.653525" limited="false" frictionloss="0.001"/>
          <geom size="0.009"/>
        </body>
        <body name="left_rear_roller_4" pos="0.068 0 8.18498e-05">
          <inertial pos="0 0 0" mass="0.036" diaginertia="3.128e-06 3.128e-06 3.128e-06"/>
          <joint name="left_rear_roller_4_joint" pos="0 0 0" axis="-0.000851125 0.707107 0.707106" limited="false" frictionloss="0.001"/>
          <geom size="0.009"/>
        </body>
        <body name="left_rear_roller_5" pos="0.0627846 0 0.026117">
          <inertial pos="0 0 0" mass="0.036" diaginertia="3.128e-06 3.128e-06 3.128e-06"/>
          <joint name="left_rear_roller_5_joint" pos="0 0 0" axis="-0.271581 0.707107 0.652874" limited="false" frictionloss="0.001"/>
          <geom size="0.009"/>
        </body>
        <body name="left_rear_roller_6" pos="0.0479964 0 0.04817">
          <inertial pos="0 0 0" mass="0.036" diaginertia="3.128e-06 3.128e-06 3.128e-06"/>
          <joint name="left_rear_roller_6_joint" pos="0 0 0" axis="-0.500902 0.707107 0.499096" limited="false" frictionloss="0.001"/>
          <geom size="0.009"/>
        </body>
        <body name="left_rear_roller_7" pos="0.0258901 0 0.0628785">
          <inertial pos="0 0 0" mass="0.036" diaginertia="3.128e-06 3.128e-06 3.128e-06"/>
          <joint name="left_rear_roller_7_joint" pos="0 0 0" axis="-0.65385 0.707107 0.269221" limited="false" frictionloss="0.001"/>
          <geom size="0.009"/>
        </body>
        <body name="left_rear_roller_8" pos="-0.000163699 0 0.0679998">
          <inertial pos="0 0 0" mass="0.036" diaginertia="3.128e-06 3.128e-06 3.128e-06"/>
          <joint name="left_rear_roller_8_joint" pos="0 0 0" axis="-0.707105 0.707107 -0.00170225" limited="false" frictionloss="0.001"/>
          <geom size="0.009"/>
        </body>
        <body name="left_rear_roller_9" pos="-0.0261925 0 0.0627531">
          <inertial pos="0 0 0" mass="0.036" diaginertia="3.128e-06 3.128e-06 3.128e-06"/>
          <joint name="left_rear_roller_9_joint" pos="0 0 0" axis="-0.652546 0.707107 -0.272366" limited="false" frictionloss="0.001"/>
          <geom size="0.009"/>
        </body>
        <body name="left_rear_roller_10" pos="-0.0482277 0 0.0479384">
          <inertial pos="0 0 0" mass="0.036" diaginertia="3.128e-06 3.128e-06 3.128e-06"/>
          <joint name="left_rear_roller_10_joint" pos="0 0 0" axis="-0.498493 0.707107 -0.501502" limited="false" frictionloss="0.001"/>
          <geom size="0.009"/>
        </body>
        <body name="left_rear_roller_11" pos="-0.0629096 0 0.0258144">
          <inertial pos="0 0 0" mass="0.036" diaginertia="3.128e-06 3.128e-06 3.128e-06"/>
          <joint name="left_rear_roller_11_joint" pos="0 0 0" axis="-0.268434 0.707107 -0.654174" limited="false" frictionloss="0.001"/>
          <geom size="0.009"/>
        </body>
        <body name="left_rear_roller_12" pos="-0.0679996 0 -0.000245549">
          <inertial pos="0 0 0" mass="0.036" diaginertia="3.128e-06 3.128e-06 3.128e-06"/>
          <joint name="left_rear_roller_12_joint" pos="0 0 0" axis="0.00255337 0.707107 -0.707102" limited="false" frictionloss="0.001"/>
          <geom size="0.009"/>
        </body>
        <body name="left_rear_roller_13" pos="-0.0627215 0 -0.026268">
          <inertial pos="0 0 0" mass="0.036" diaginertia="3.128e-06 3.128e-06 3.128e-06"/>
          <joint name="left_rear_roller_13_joint" pos="0 0 0" axis="0.273152 0.707107 -0.652218" limited="false" frictionloss="0.001"/>
          <geom size="0.009"/>
        </body>
        <body name="left_rear_roller_14" pos="-0.0478803 0 -0.0482854">
          <inertial pos="0 0 0" mass="0.036" diaginertia="3.128e-06 3.128e-06 3.128e-06"/>
          <joint name="left_rear_roller_14_joint" pos="0 0 0" axis="0.502102 0.707107 -0.497889" limited="false" frictionloss="0.001"/>
          <geom size="0.009"/>
        </body>
        <body name="left_rear_roller_15" pos="-0.0257386 0 -0.0629406">
          <inertial pos="0 0 0" mass="0.036" diaginertia="3.128e-06 3.128e-06 3.128e-06"/>
          <joint name="left_rear_roller_15_joint" pos="0 0 0" axis="0.654496 0.707107 -0.267647" limited="false" frictionloss="0.001"/>
          <geom size="0.009"/>
        </body>
      </body>
      <body name="right_rear_wheel" pos="-0.19727 -0.223 0.000889">
        <inertial pos="0 0 0" quat="0.707107 0 0 0.707107" mass="0.4235" diaginertia="0.0007398 0.0004122 0.0004122"/>
        <joint name="right_rear_wheel_joint" pos="0 0 0" axis="0 1 0" limited="true" range="-1000000000 1000000000" frictionloss="0.05"/>
        <geom type="mesh" contype="0" conaffinity="0" group="1" density="0" rgba="0.792157 0.819608 0.933333 1" mesh="right_mecanum_wheel"/>
        <body name="right_rear_roller_0" pos="0 0 -0.068">
          <inertial pos="0 0 0" mass="0.036" diaginertia="3.128e-06 3.128e-06 3.128e-06"/>
          <joint name="right_rear_roller_0_joint" pos="0 0 0" axis="0.707107 -0.707107 0" limited="false" frictionloss="0.001"/>
          <geom size="0.009"/>
        </body>
        <body name="right_rear_roller_1" pos="0.0260414 0 -0.062816">
          <inertial pos="0 0 0" mass="0.036" diaginertia="3.128e-06 3.128e-06 3.128e-06"/>
          <joint name="right_rear_roller_1_joint" pos="0 0 0" axis="0.6532 -0.707107 0.270795" limited="false" frictionloss="0.001"/>
          <geom size="0.009"/>
        </body>
        <body name="right_rear_roller_2" pos="0.0481122 0 -0.0480543">
          <inertial pos="0 0 0" mass="0.036" diaginertia="3.128e-06 3.128e-06 3.128e-06"/>
          <joint name="right_rear_roller_2_joint" pos="0 0 0" axis="0.499699 -0.707107 0.500301" limited="false" frictionloss="0.001"/>
          <geom size="0.009"/>
        </body>
        <body name="right_rear_roller_3" pos="0.0628473 0 -0.0259657">
          <inertial pos="0 0 0" mass="0.036" diaginertia="3.128e-06 3.128e-06 3.128e-06"/>
          <joint name="right_rear_roller_3_joint" pos="0 0 0" axis="0.270008 -0.707107 0.653525" limited="false" frictionloss="0.001"/>
          <geom size="0.009"/>
        </body>
        <body name="right_rear_roller_4" pos="0.068 0 8.18498e-05">
          <inertial pos="0 0 0" mass="0.036" diaginertia="3.128e-06 3.128e-06 3.128e-06"/>
          <joint name="right_rear_roller_4_joint" pos="0 0 0" axis="-0.000851125 -0.707107 0.707106" limited="false" frictionloss="0.001"/>
          <geom size="0.009"/>
        </body>
        <body name="right_rear_roller_5" pos="0.0627846 0 0.026117">
          <inertial pos="0 0 0" mass="0.036" diaginertia="3.128e-06 3.128e-06 3.128e-06"/>
          <joint name="right_rear_roller_5_joint" pos="0 0 0" axis="-0.271581 -0.707107 0.652874" limited="false" frictionloss="0.001"/>
          <geom size="0.009"/>
        </body>
        <body name="right_rear_roller_6" pos="0.0479964 0 0.04817">
          <inertial pos="0 0 0" mass="0.036" diaginertia="3.128e-06 3.128e-06 3.128e-06"/>
          <joint name="right_rear_roller_6_joint" pos="0 0 0" axis="-0.500902 -0.707107 0.499096" limited="false" frictionloss="0.001"/>
          <geom size="0.009"/>
        </body>
        <body name="right_rear_roller_7" pos="0.0258901 0 0.0628785">
          <inertial pos="0 0 0" mass="0.036" diaginertia="3.128e-06 3.128e-06 3.128e-06"/>
          <joint name="right_rear_roller_7_joint" pos="0 0 0" axis="-0.65385 -0.707107 0.269221" limited="false" frictionloss="0.001"/>
          <geom size="0.009"/>
        </body>
        <body name="right_rear_roller_8" pos="-0.000163699 0 0.0679998">
          <inertial pos="0 0 0" mass="0.036" diaginertia="3.128e-06 3.128e-06 3.128e-06"/>
          <joint name="right_rear_roller_8_joint" pos="0 0 0" axis="-0.707105 -0.707107 -0.00170225" limited="false" frictionloss="0.001"/>
          <geom size="0.009"/>
        </body>
        <body name="right_rear_roller_9" pos="-0.0261925 0 0.0627531">
          <inertial pos="0 0 0" mass="0.036" diaginertia="3.128e-06 3.128e-06 3.128e-06"/>
          <joint name="right_rear_roller_9_joint" pos="0 0 0" axis="-0.652546 -0.707107 -0.272366" limited="false" frictionloss="0.001"/>
          <geom size="0.009"/>
        </body>
        <body name="right_rear_roller_10" pos="-0.0482277 0 0.0479384">
          <inertial pos="0 0 0" mass="0.036" diaginertia="3.128e-06 3.128e-06 3.128e-06"/>
          <joint name="right_rear_roller_10_joint" pos="0 0 0" axis="-0.498493 -0.707107 -0.501502" limited="false" frictionloss="0.001"/>
          <geom size="0.009"/>
        </body>
        <body name="right_rear_roller_11" pos="-0.0629096 0 0.0258144">
          <inertial pos="0 0 0" mass="0.036" diaginertia="3.128e-06 3.128e-06 3.128e-06"/>
          <joint name="right_rear_roller_11_joint" pos="0 0 0" axis="-0.268434 -0.707107 -0.654174" limited="false" frictionloss="0.001"/>
          <geom size="0.009"/>
        </body>
        <body name="right_rear_roller_12" pos="-0.0679996 0 -0.000245549">
          <inertial pos="0 0 0" mass="0.036" diaginertia="3.128e-06 3.128e-06 3.128e-06"/>
          <joint name="right_rear_roller_12_joint" pos="0 0 0" axis="0.00255337 -0.707107 -0.707102" limited="false" frictionloss="0.001"/>
          <geom size="0.009"/>
        </body>
        <body name="right_rear_roller_13" pos="-0.0627215 0 -0.026268">
          <inertial pos="0 0 0" mass="0.036" diaginertia="3.128e-06 3.128e-06 3.128e-06"/>
          <joint name="right_rear_roller_13_joint" pos="0 0 0" axis="0.273152 -0.707107 -0.652218" limited="false" frictionloss="0.001"/>
          <geom size="0.009"/>
        </body>
        <body name="right_rear_roller_14" pos="-0.0478803 0 -0.0482854">
          <inertial pos="0 0 0" mass="0.036" diaginertia="3.128e-06 3.128e-06 3.128e-06"/>
          <joint name="right_rear_roller_14_joint" pos="0 0 0" axis="0.502102 -0.707107 -0.497889" limited="false" frictionloss="0.001"/>
          <geom size="0.009"/>
        </body>
        <body name="right_rear_roller_15" pos="-0.0257386 0 -0.0629406">
          <inertial pos="0 0 0" mass="0.036" diaginertia="3.128e-06 3.128e-06 3.128e-06"/>
          <joint name="right_rear_roller_15_joint" pos="0 0 0" axis="0.654496 -0.707107 -0.267647" limited="false" frictionloss="0.001"/>
          <geom size="0.009"/>
        </body>
      </body>
      <body name="imu_frame"/>
    </body>
  </worldbody>
  <actuator>
    <velocity name="right_front_wheel_joint" joint="right_front_wheel_joint"/>
    <velocity name="right_rear_wheel_joint" joint="right_rear_wheel_joint"/>
    <velocity name="left_front_wheel_joint" joint="left_front_wheel_joint"/>
    <velocity name="left_rear_wheel_joint" joint="left_rear_wheel_joint"/>
  </actuator>
</mujoco>
